Workbook

Sheet 0. Investment Committee
B2: ClaimPulse · Investment Committee Summary
B3: Team Finsighters · NMIMS Mumbai · PS_BFDL Motor Insurance Claims TAT. One page. Every figure on it is live from the model behind it; the tab reference tells you where.
B4: All figures at the Base plan: 60 per cent rollout of the addressable Motor OD book, filed FY2026 net-earned-premium basis.
B6: 1. THE ASK
B7: Ref | C7: Item | D7: Value | G7: Basis
B8: IC-01 | C8: Capital requested, build (one-off) | D8: ='3. Workings'!$D$55 -> 9.8904698 | G8: Fifteen costed components, Sheet 3 Part D
B9: IC-02 | C9: Capital requested, fully loaded | D9: ='5. Investor Metrics'!$E$36 -> 11.37404 | G9: Build plus a 15 per cent contingency, Sheet 5 RE-04
B10: IC-03 | C10: Annual run cost at steady state | D10: ='3. Workings'!$E$65 -> 3.9006065 | G10: Six lines, Sheet 3 Part E
B11: IC-04 | C11: Three-year total cost of ownership | D11: ='5. Investor Metrics'!$C$51 -> 22.639871 | G11: Build plus three years of run cost, Sheet 5 Part D
B12: All rupee figures in crore unless stated. The build sits with BFDL; the underwriting benefit lands in Bajaj General. Sheet 3 Part I splits every rupee by the entity that books it.
B14: 2. THE RETURN
B15: Ref | C15: Measure | D15: Conservative | E15: Base | F15: Aggressive | G15: What it means
B16: IC-05 | C16: Rollout of the addressable book | D16: ='3. Workings'!$D$12 -> 0.2 | E16: ='3. Workings'!$E$12 -> 0.6 | F16: ='3. Workings'!$F$12 -> 1 | G16: The only lever that separates the three plans.
B17: IC-06 | C17: Net annual benefit, steady state | D17: ='3. Workings'!$D$71 -> 12.85009 | E17: ='3. Workings'!$E$71 -> 43.310005 | F17: ='3. Workings'!$F$71 -> 75.277514 | G17: Gross benefit less full annual run cost.
B18: IC-07 | C18: Payback from project kickoff | D18: ='4. Forecast'!$D$50 -> 27.21363 | E18: ='4. Forecast'!$E$50 -> 16.842971 | F18: ='4. Forecast'!$F$50 -> 13.83294 | G18: Includes the ten-month build window with no benefit. The figure the deck quotes.
B19: IC-08 | C19: Five-year NPV at 12 per cent | D19: ='5. Investor Metrics'!$D$28 -> 35.585967 | E19: ='5. Investor Metrics'!$E$28 -> 145.93821 | F19: ='5. Investor Metrics'!$F$28 -> 261.79085 | G19: Project DCF, Sheet 5 Part B.
B20: IC-09 | C20: Combined ratio impact, Motor OD basis | D20: ='3. Workings'!$D$82 -> 0.76499125 | E20: ='3. Workings'!$E$82 -> 2.5826285 | F20: ='3. Workings'!$F$82 -> 4.4913773 | G20: Loss ratio plus expense ratio, against Motor OD earned premium.
B21: IC-10 | C21: Claim TAT, whole Motor OD book | D21: ='3. Workings'!$D$24 -> 8.382 | E21: ='3. Workings'!$E$24 -> 5.546 | F21: ='3. Workings'!$F$24 -> 2.71 | G21: Against 9.8 days today. Platform TAT on the rolled-out share.
B22: IC-11 | C22: Cost to serve per claim, after | D22: ='5. Investor Metrics'!$D$9 -> 369 | E22: ='5. Investor Metrics'!$E$9 -> 307.5 | F22: ='5. Investor Metrics'!$F$9 -> 246 | G22: Against Rs 1,750 today, identical across plans.
B23: IC-12 | C23: FTE capacity released | D23: ='3. Workings'!$D$113 -> 58.620505 | E23: ='3. Workings'!$E$113 -> 175.86152 | F23: ='3. Workings'!$F$113 -> 293.10253 | G23: Redeployed to complex claims, not removed.
B26: 3. THE DOWNSIDE · what has to go wrong, and what is left when it does
B27: Ref | C27: Case | D27: Net annual | E27: 5-yr NPV | F27: Payback, mo | G27: What is assumed
B28: IC-13 | C28: As modelled | D28: ='3. Workings'!$D$183 -> 43.310005 | E28: ='3. Workings'!$D$190 -> 145.93821 | F28: ='3. Workings'!$D$191 -> 16.842971 | G28: Base plan on published assumptions.
B29: IC-14 | C29: Operating reality misses | D29: ='3. Workings'!$E$183 -> 25.114505 | E29: ='3. Workings'!$E$190 -> 79.552766 | F29: ='3. Workings'!$E$191 -> 22.355635 | G29: In-house handling at Rs 83 a touch and five baseline touches.
B30: IC-15 | C30: Fraud disappoints | D30: ='3. Workings'!$F$183 -> 27.245157 | E30: ='3. Workings'!$F$190 -> 87.326352 | F30: ='3. Workings'!$F$191 -> 21.733642 | G30: Detection lands at 82 per cent, leakage halves, synthetic incidence quarters.
B31: IC-16 | C31: Adoption drags | D31: ='3. Workings'!$G$183 -> 23.557645 | E31: ='3. Workings'!$G$190 -> 74.35973 | F31: ='3. Workings'!$G$191 -> 22.49288 | G31: Rollout 35 per cent, green lane 50 per cent, live-capture friction doubled.
B32: IC-17 | C32: ALL THREE AT ONCE | D32: ='3. Workings'!$H$183 -> 4.2073585 | E32: ='3. Workings'!$H$190 -> 3.7610998 | F32: ='3. Workings'!$H$191 -> 47.66379 | G32: Every one of the above, applied together. Sheet 3 Part L.
B33: IC-18 | C33: Labour only, zero fraud benefit | D33: ='3. Workings'!$E$94 -> 3.7847953 | F33: ='3. Workings'!$E$97 -> 31.358536 | G33: No fraud, gate, synthetic or renewal value at all. Sheet 3 Part H.
B34: IC-19 | C34: INVESTOR GATE — five-year NPV positive in every case above? | D34: =IF(MIN('3. Workings'!$D$190,'3. Workings'!$E$190,'3. Workings'!$F$190,'3. Workings'!$G$190,'3. Workings'!$H$190)>0,"PASS","REVIEW") -> PASS | G34: Tested on the correlated case, not on the headline.
B35: No single assumption carries this case. Three separate things have to disappoint at the same time before the return compresses materially, and the build still repays even then.
B37: 4. EVIDENCE POSITION
B38: Ref | C38: Check | D38: Result | G38: Where it is done
B39: IC-20 | C39: Claim frequency implied by the model | D39: ='3. Workings'!$D$153 -> 0.057882969 | G39: Sheet 3 Part K. Industry norm is 5 to 15 per cent.
B40: IC-21 | C40: Frequency reconciliation | D40: ='3. Workings'!$D$155 -> PASS - inside the 5 to 15 per cent band | G40: B-01 and B-21 cross-check to an in-band frequency.
B41: IC-22 | C41: Stakeholder split ties to the P&L | D41: =IF(ABS('3. Workings'!$E$105)<0.0001,"TIE","REVIEW") -> TIE | G41: Sheet 3 W-60. Every rupee is attributed to an entity.
B42: IC-23 | C42: Scenario engine ties to the model | D42: ='8. Scenario Simulation'!$D$14 -> ALL SIX ANCHORS TIE - Part B is live against the current engine | G42: Sheet 8 Part A, six anchors.
B43: IC-24 | C43: Net earned premium basis | D43: ='1. Assumptions and Sources'!$D$8 -> 0.4988 | G43: Filed FY2026. Sheet 1 Table P carries three bases; Sheet 3 Part M restates the case on each.
B44: IC-25 | C44: Case on the Motor OD retention basis | D44: ='3. Workings'!$G$203 -> 60.471437 | G44: Sheet 3 Part M. The headline basis is the conservative one.
B46: 5. WHAT WE NEED FROM BAJAJ, AND WHAT WE COMMIT TO PROVE
B47: Ref | C47: Item | D47: Owner | G47: Why it matters
...

Sheet Navigation
B2: ClaimPulse · Navigation
B3: Team Finsighters · NMIMS Mumbai · PS_BFDL Motor Insurance Claims TAT Reduction. Fifteen tabs. Click any tab name below to jump to it. Start at Sheet 0.
B4: THE ONE-LINE VERSION. A Rs 9.89 Cr build returns Rs 43.31 Cr a year at the Base plan, repays from project kickoff in 16.8 months, moves the Motor OD combined ratio by 2.58 pp, and stays NPV positive even when the operating, fraud and adoption assumptions all miss at the same time.
B5: HOW IT IS BUILT. Sheet 1 holds every input with a source and an evidence tier. Sheets 2 to 6 are pure formula and contain no typed numbers. Sheets 7 to 13 carry the evidence base, the stress testing and the architecture decisions. Sheet 0 is the one page an investment committee reads.
B7: THE MODEL · the numbers, and how they are produced
B8: Tab | C8: What it is | D8: What you will find here | E8: Go here first for
B9: Dashboard | C9: The one-page investor view | D9: Headline KPIs, the stakeholder scorecard, five-year cumulative value, and LIVE CHALLENGE LEVERS where you can type a value and watch the model move | E9: A five-minute read of the whole case
B10: 1. Assumptions and Sources | C10: Every input, every source | D10: Every input with a source and an evidence tier. Table G sets out how each line is constructed. Table H and Table N are the sensitivity register: which inputs move the answer and how each is validated. Table P carries three net-earned-premium bases; Table Q carries the rates that change inside the window. | E10: Checking whether a number is defensible
B11: 2. Summary | C11: The headline figures | D11: 19 headline metrics across Conservative, Base and Aggressive. Where the benefit comes from, line by line. The 24 self-audit integrity checks | E11: The investment case on one screen
B12: 3. Workings | C12: The engine | D12: The full chain from filed premium to net benefit. Part G is the insurance P&L bridge, Part H the downside tests, Part J the break-even analysis, Part K the claim-frequency reconciliation, Part L the correlated stress test, Part M the same case on three net-earned-premium bases. | E12: Understanding how a number was derived
B13: 4. Forecast | C13: Three-year view | D13: Year by year benefit, cost and cumulative position on the ramp convention | E13: The multi-year picture
B14: 5. Investor Metrics | C14: Return metrics | D14: NPV, IRR, ROIC, EVA and the unit economics block | E14: Anything an investment committee asks
B15: 6. Stakeholder Analysis | C15: Who gets what | D15: Quantified value split by stakeholder, every row a formula reading the P&L | E15: Who benefits, and who carries a cost
B16: 0. Investment Committee | C16: The one page that decides | D16: The ask, the return across all three plans, the correlated downside, the evidence position, the five data requests and the four pilot gates with their kill criteria. Every figure is live from the model behind it. | E16: Reading the case in two minutes
B17: THE RESEARCH · what could change, and what we would do about it
B18: Tab | C18: What it is | D18: What you will find here | E18: Go here first for
B19: 7. Trend Analysis | C19: The evidence base | D19: Twenty-one trends, each with a named publisher, a date and an evidence class. The four-domain trend vector map. The evidence gaps, carried openly with the handling for each. A full evidence-class summary. | E19: Where a fact came from, and whether it holds
B20: 8. Scenario Simulation | C20: Stress testing | D20: A live engine check that must tie before anything below it counts. Five scenarios at three intensities, all computed live from the engine. The correlated stress test sits at Sheet 3 Part L. Cross-domain synthesis and the scenario library. | E20: What breaks the case, and what does not
B21: 9. Landscape Impact | C21: The wider consequence | D21: All 17 scenarios across eight landscape dimensions, grouped into eight themes: market structure, ecosystem, regulation, business model, capital, talent, moat and demand | E21: What each scenario does beyond the P&L
B22: 10. Resilience and Breakpoints | C22: Where it stops working | D22: Nine named breakpoints, five computable today. Three resilience dimensions reported separately, never averaged. Component dependency matrix. What each severity grade means, and how the platform repurposes at the worst one | E22: The honest limits of the case
B23: 11. Strategy and Early Warning | C23: The response | D23: Strategic response per scenario, quarterly indicators to monitor, the management question for each, ten driver-interaction mechanisms, and a 31-metric KPI framework across seven layers | E23: What management should do, and watch
B25: SUGGESTED READING PATH
B26: 1. | C26: Sheet 0 Investment Committee. That is the case. Sheet 2 Summary if you want the same thing with more lines.
B27: 2. | C27: Sheet 8 Part A. Confirm the six engine anchors tie before trusting any scenario number below them.
B28: 3. | C28: Sheet 3 Part L. The correlated downside: what is left when the operating, fraud and adoption assumptions all miss together.
B29: 4. | C29: Sheet 1 Table H. The sensitivity register: which assumptions move the answer, and how each is validated.
B30: 5. | C30: Sheet 10 Part A. The nine breakpoints, including the one the pilot is designed to measure first.
B31: 6. | C31: Sheets 7, 9, 10 and 11 as reference, when a specific trend, consequence, breakpoint or response is queried.
B33: THREE THINGS TO KNOW BEFORE QUOTING A NUMBER
B34: 1. | C34: Combined ratio is reported on two bases and they are not interchangeable. 2.58 pp on a Motor OD basis is 0.42 pp on the group book. Never subtract the Motor OD figure from a group combined ratio.
B35: 2. | C35: Payback from project kickoff, Sheet 4 FS-05, is the figure the deck quotes. It includes the ten-month build window. The steady-state figure on Sheet 3 Part F is shorter because it excludes that window.
B36: 3. | C36: Net earned premium runs on the filed FY2026 basis. Sheet 1 Table P and Sheet 3 Part M carry the other two bases; the case is stronger on the Motor OD retention basis, so the headline is the conservative one.
B38: Sheet numbering on this page matches the tab names exactly. Sheets 12 and 13 sit below because they were added as the cost and architecture annexures.
B40: 12. Cost Architecture | C40: Where the money goes | D40: The full build and run cost stack, the nine decisions taken to reduce it, fixed versus variable ceiling, build-versus-buy on verified vendor rates, and the unpriced value of Bajaj's historical claim-image archive | E40: Any question about cost, efficiency or AI spend
B42: 13. GenAI Build vs Buy | C42: The architecture decision | D42: Incremental five-year cost of adding generative AI via API versus self-hosting, with the baseline conventional-ML and moat layers netted out. Part G re-runs the decision on the rate card that applies from 1 September 2026. | E42: Whether to buy or build the GenAI layer

Sheet Dashboard
D2: Claims Pulse | S2: Executive Business Case Dashboard | CZ2: Section 1 helper tables | DB2: Section 2 — Financial Impact | DD2: Section 3 — Investment Case | DH2: Section 1 helper tables — STAKEHOLDER IMPACT
BH3: Scenario
BH4: Aggressive | CZ4: Table A — TAT comparison | DB4: Chart 1 — Annual Benefit Composition | DD4: Five-Year Cumulative Value Chart | DH4: Table S1 — Value split by beneficiary (Rs Cr)
D5: AI Powered Claims Transformation | S5: Transforming Motor OD Claims | Faster. Smarter. Fraud - Resilient | CZ5: Metric | DA5: Value | DB5: Benefit Component | DC5: Value | DD5: Year | DE5: Annual Net Cash Flow | DF5: Cumulative Net Position | DH5: Beneficiary | DI5: Value
BH6: All values in Rs. Cr unless stated otherwise. | CZ6: Current | DA6: =INDEX('3. Workings'!$D$22:$F$22,MATCH($BH$4,'3. Workings'!$D$6:$F$6,0)) -> 9.8 | DB6: Labour | DC6: =INDEX('3. Workings'!$D$30:$F$30,MATCH($BH$4,'3. Workings'!$D$68:$F$68,0)) -> 41.255831 | DD6: Year 0 | DE6: =INDEX('5. Investor Metrics'!$D$21:$F$21,MATCH($BH$4,'5. Investor Metrics'!$D$20:$F$20,0)) -> -9.8904698 | DF6: =DE6 -> -9.8904698 | DH6: Claims operations (expense ratio) | DI6: =INDEX('3. Workings'!$D$101:$F$101,MATCH($BH$4,'3. Workings'!$D$100:$F$100,0)) -> 40.465826
CZ7: ClaimPulse – Selected Scenario | DA7: =INDEX('3. Workings'!$D$24:$F$24,MATCH($BH$4,'3. Workings'!$D$6:$F$6,0)) -> 2.71 | DB7: Fraud Graph | DC7: =INDEX('3. Workings'!$D$31:$F$31,MATCH($BH$4,'3. Workings'!$D$68:$F$68,0)) -> 18.418297 | DD7: Year 1 | DE7: =INDEX('5. Investor Metrics'!$D$22:$F$22,MATCH($BH$4,'5. Investor Metrics'!$D$20:$F$20,0)) -> 30.964649 | DF7: =DF6+DE7 -> 21.074179 | DH7: Underwriting (loss ratio) | DI7: =INDEX('3. Workings'!$D$102:$F$102,MATCH($BH$4,'3. Workings'!$D$100:$F$100,0)) -> 39.142943
DB8: Synthetic Media | DC8: =INDEX('3. Workings'!$D$33:$F$33,MATCH($BH$4,'3. Workings'!$D$68:$F$68,0)) -> 10.492258 | DD8: Year 2 | DE8: =INDEX('5. Investor Metrics'!$D$23:$F$23,MATCH($BH$4,'5. Investor Metrics'!$D$20:$F$20,0)) -> 74.820391 | DF8: =DF7+DE8 -> 95.89457 | DH8: BFDL distribution (renewal) | DI8: =INDEX('3. Workings'!$D$103:$F$103,MATCH($BH$4,'3. Workings'!$D$100:$F$100,0)) -> 0.96007586
DB9: Capture Integrity Gate | DC9: =INDEX('3. Workings'!$D$32:$F$32,MATCH($BH$4,'3. Workings'!$D$68:$F$68,0)) -> 10.232387 | DD9: Year 3 | DE9: =INDEX('5. Investor Metrics'!$D$24:$F$24,MATCH($BH$4,'5. Investor Metrics'!$D$20:$F$20,0)) -> 88.945577 | DF9: =DF8+DE9 -> 184.84015
D10: =IF((INDEX('3. Workings'!$D$13:$F$13,MATCH($BH$4,'3. Workings'!$D$6:$F$6,0)))>=1000000000,TEXT((INDEX('3. Workings'!$D$13:$F$13,MATCH($BH$4,'3. Workings'!$D$6:$F$6,0)))/1000000000,"0.0")&"B Claims",IF((INDEX('3. Workings'!$D$13:$F$13,MATCH($BH$4,'3. Workings'!$D$6:$F$6,0)))>=1000000,TEXT((INDEX('3. Workings'!$D$13:$F$13,MATCH($BH$4,'3. Workings'!$D$6:$F$6,0)))/1000000,"0.0")&"M Claims",IF((INDEX('3. Workings'!$D$13:$F$13,MATCH($BH$4,'3. Workings'!$D$6:$F$6,0)))>=1000,TEXT((INDEX('3. Workings'!$D$13:$F$13,MATCH($BH$4,'3. Workings'!$D$6:$F$6,0)))/1000,"0.0")&"K Claims",TEXT((INDEX('3. Workings'!$D$13:$F$13,MATCH($BH$4,'3. Workings'!$D$6:$F$6,0))),"0.0")&" Claims"))) -> 274.3K Claims | S10: =TEXT(INDEX('3. Workings'!$D$22:$F$22,MATCH($BH$4,'3. Workings'!$D$6:$F$6,0)),"0.0")&" Days" -> 9.8 Days | AB10: =TEXT(INDEX('3. Workings'!$D$24:$F$24,MATCH($BH$4,'3. Workings'!$D$6:$F$6,0)),"0.0")&" Days" -> 2.7 Days | AN10: =TEXT(INDEX('3. Workings'!$D$26:$F$26,MATCH($BH$4,'3. Workings'!$D$6:$F$6,0)),"0.0%") -> 72.3% | BC10: ="₹"&TEXT(INDEX('3. Workings'!$D$71:$F$71,MATCH($BH$4,'3. Workings'!$D$68:$F$68,0)),"0.0")&" Cr" -> ₹75.3 Cr | BR10: =TEXT(INDEX('4. Forecast'!$D$50:$F$50,MATCH($BH$4,'4. Forecast'!$D$45:$F$45,0)),"0.0")&" Months" -> 13.8 Months | CG10: =TEXT(INDEX('3. Workings'!$D$82:$F$82,MATCH($BH$4,'3. Workings'!$D$77:$F$77,0)),"0.0")&" pp" -> 4.5 pp | CZ10: Table B — Manual touches | DB10: Renewal | DC10: =INDEX('3. Workings'!$D$34:$F$34,MATCH($BH$4,'3. Workings'!$D$68:$F$68,0)) -> 0.96007586 | DD10: Year 4 | DE10: =INDEX('5. Investor Metrics'!$D$25:$F$25,MATCH($BH$4,'5. Investor Metrics'!$D$20:$F$20,0)) -> 96.683842 | DF10: =DF9+DE10 -> 281.52399 | DH10: Table S2 — Claimant impact
CZ11: Metric | DA11: Value | DB11: Friction Cost | DC11: =INDEX('3. Workings'!$D$35:$F$35,MATCH($BH$4,'3. Workings'!$D$68:$F$68,0)) -> -0.79000528 | DD11: Year 5 | DE11: =INDEX('5. Investor Metrics'!$D$26:$F$26,MATCH($BH$4,'5. Investor Metrics'!$D$20:$F$20,0)) -> 105.09534 | DF11: =DF10+DE11 -> 386.61932 | DH11: Metric | DI11: Value
D12: Annual vol. at selected scenario | S12: Current | AB12: ClaimPulse | AN12: Reduction | BC12: Benefit | BR12: From Project Kickoff | CG12: Improvement vs. Current | CZ12: Current – Whole Book | DA12: =INDEX('1. Assumptions and Sources'!$D$23:$D$45,MATCH("Manual touches per claim today",'1. Assumptions and Sources'!$C$23:$C$45,0)) -> 7 | DH12: Claimant-days returned per year | DI12: =INDEX('3. Workings'!$D$107:$F$107,MATCH($BH$4,'3. Workings'!$D$100:$F$100,0)) -> 1944839.4
CZ13: ClaimPulse – Whole Book | DA13: =(INDEX('3. Workings'!$D$12:$F$12,MATCH($BH$4,'3. Workings'!$D$6:$F$6,0)))*(INDEX('3. Workings'!$D$19:$F$19,MATCH($BH$4,'3. Workings'!$D$6:$F$6,0)))+(1-(INDEX('3. Workings'!$D$12:$F$12,MATCH($BH$4,'3. Workings'!$D$6:$F$6,0))))*(INDEX('1. Assumptions and Sources'!$D$23:$D$45,MATCH("Manual touches per claim today",'1. Assumptions and Sources'!$C$23:$C$45,0))) -> 1.23 | DH13: Claims auto-settled, zero human touch | DI13: =INDEX('3. Workings'!$D$108:$F$108,MATCH($BH$4,'3. Workings'!$D$100:$F$100,0)) -> 178299.8
DB14: 2. Annual Run Cost — Helper Table | DH14: Claims still reviewed by a human | DI14: =INDEX('3. Workings'!$D$109:$F$109,MATCH($BH$4,'3. Workings'!$D$100:$F$100,0)) -> 96007.586
DH15: TAT saved per on-platform claim (days) | DI15: =INDEX('3. Workings'!$D$106:$F$106,MATCH($BH$4,'3. Workings'!$D$100:$F$100,0)) -> 7.09
CL16: ="Selected scenario: "&$BH$4 -> Selected scenario: Aggressive | CZ16: Table C — Annual manual touches avoided | DB16: Cost Component | DC16: Value | DD16: Section 4 - Investment P&L | DH16: Share of book still on 9.8-day journey | DI16: =INDEX('3. Workings'!$D$110:$F$110,MATCH($BH$4,'3. Workings'!$D$100:$F$100,0)) -> 0
CZ17: Metric | DA17: Value | DB17: GPU Compute | DC17: =INDEX('3. Workings'!$D$59:$F$59,MATCH($BH$4,'3. Workings'!$D$58:$F$58,0)) -> 3.1369715
D18: ="WHERE THE GROSS BENEFIT LANDS · ₹"&TEXT(DI6+DI7+DI8,"0.0")&" Cr" -> WHERE THE GROSS BENEFIT LANDS · ₹80.6 Cr | AG18: WHAT THE CLAIMANT GETS | BI18: CAPACITY RELEASED, NOT HEADCOUNT CUT | CZ18: Current annual touches | DA18: =(INDEX('3. Workings'!$D$11:$F$11,MATCH($BH$4,'3. Workings'!$D$6:$F$6,0)))*(INDEX('1. Assumptions and Sources'!$D$23:$D$45,MATCH("Manual touches per claim today",'1. Assumptions and Sources'!$C$23:$C$45,0))) -> 1920151.7 | DB18: Storage | DC18: =INDEX('3. Workings'!$D$60:$F$60,MATCH($BH$4,'3. Workings'!$D$58:$F$58,0)) -> 0.33983942 | DD18: Helper Table A — Motor OD P&L Bridge | DH18: Table S3 — Claims workforce
CZ19: After ClaimPulse annual touches | DA19: =(INDEX('3. Workings'!$D$11:$F$11,MATCH($BH$4,'3. Workings'!$D$6:$F$6,0)))*((INDEX('3. Workings'!$D$12:$F$12,MATCH($BH$4,'3. Workings'!$D$6:$F$6,0)))*(INDEX('3. Workings'!$D$19:$F$19,MATCH($BH$4,'3. Workings'!$D$6:$F$6,0)))+(1-(INDEX('3. Workings'!$D$12:$F$12,MATCH($BH$4,'3. Workings'!$D$6:$F$6,0))))*(INDEX('1. Assumptions and Sources'!$D$23:$D$45,MATCH("Manual touches per claim today",'1. Assumptions and Sources'!$C$23:$C$45,0)))) -> 337398.09 | DB19: MLOps | DC19: =INDEX('3. Workings'!$D$61:$F$61,MATCH($BH$4,'3. Workings'!$D$58:$F$58,0)) -> 0.80052 | DD19: Metric | DE19: Value | DH19: Metric | DI19: Value
AH20: =TEXT(DI12/100000,"0.0")&" lakh claimant-days returned" -> 19.4 lakh claimant-days returned | DB20: Operations | DC20: =INDEX('3. Workings'!$D$62:$F$62,MATCH($BH$4,'3. Workings'!$D$58:$F$58,0)) -> 0.6440004 | DD20: Loss Ratio Improvement | DE20: =INDEX('3. Workings'!$D$80:$F$80,MATCH($BH$4,'3. Workings'!$D$77:$F$77,0)) -> 2.3656053 | DH20: Manual touches avoided per year | DI20: =INDEX('3. Workings'!$D$111:$F$111,MATCH($BH$4,'3. Workings'!$D$100:$F$100,0)) -> 1582753.6
CZ21: Table D — Claim Lane Mix | DB21: Security & Compliance | DC21: =INDEX('3. Workings'!$D$63:$F$63,MATCH($BH$4,'3. Workings'!$D$58:$F$58,0)) -> 0.2499996 | DD21: Expense Ratio Improvement | DE21: =INDEX('3. Workings'!$D$81:$F$81,MATCH($BH$4,'3. Workings'!$D$77:$F$77,0)) -> 2.125772 | DH21: Claims-handling hours released | DI21: =INDEX('3. Workings'!$D$112:$F$112,MATCH($BH$4,'3. Workings'!$D$100:$F$100,0)) -> 527584.55
CZ22: Metric | DA22: Value | DB22: Legal & Regulatory | DC22: =INDEX('3. Workings'!$D$64:$F$64,MATCH($BH$4,'3. Workings'!$D$58:$F$58,0)) -> 0.12 | DD22: Motor OD Combined Ratio Improvement | DE22: =INDEX('3. Workings'!$D$82:$F$82,MATCH($BH$4,'3. Workings'!$D$77:$F$77,0)) -> 4.4913773 | DH22: FTE capacity released | DI22: =INDEX('3. Workings'!$D$113:$F$113,MATCH($BH$4,'3. Workings'!$D$100:$F$100,0)) -> 293.10253
CZ23: Straight through (Green) | DA23: =INDEX('1. Assumptions and Sources'!$D$23:$D$45,MATCH("Green lane share",'1. Assumptions and Sources'!$C$23:$C$45,0)) -> 0.65 | DB23: Total Annual Run Cost | DC23: =INDEX('3. Workings'!$D$65:$F$65,MATCH($BH$4,'3. Workings'!$D$58:$F$58,0)) -> 5.2913309 | DH23: Adjuster throughput multiple | DI23: =INDEX('3. Workings'!$D$114:$F$114,MATCH($BH$4,'3. Workings'!$D$100:$F$100,0)) -> 5.6910569
CZ24: Complex (Amber) | DA24: =INDEX('1. Assumptions and Sources'!$D$23:$D$45,MATCH("Amber lane share",'1. Assumptions and Sources'!$C$23:$C$45,0)) -> 0.25
CZ25: Investigation (Red) | DA25: =INDEX('1. Assumptions and Sources'!$D$23:$D$45,MATCH("Red lane share",'1. Assumptions and Sources'!$C$23:$C$45,0)) -> 0.1 | DB25: 3. Financial Bridge | DH25: Table S4 — Surveyor deployment
DB26: Metric | DC26: Value | DH26: Metric | DI26: Value
CZ27: Table E - Cost per claim | DB27: Gross Annual Benefit | DC27: =INDEX('3. Workings'!$D$69:$F$69,MATCH($BH$4,'3. Workings'!$D$68:$F$68,0)) -> 80.568845 | DH27: Physical surveys — today | DI27: =INDEX('3. Workings'!$D$115:$F$115,MATCH($BH$4,'3. Workings'!$D$100:$F$100,0)) -> 150869.06
CZ28: Metric | DA28: Value | DB28: Annual Run Cost | DC28: =-INDEX('3. Workings'!$D$70:$F$70,MATCH($BH$4,'3. Workings'!$D$68:$F$68,0)) -> -5.2913309 | DH28: Physical surveys — ClaimPulse | DI28: =INDEX('3. Workings'!$D$116:$F$116,MATCH($BH$4,'3. Workings'!$D$100:$F$100,0)) -> 27430.739
DB29: Net Annual Benefit | DC29: =INDEX('3. Workings'!$D$71:$F$71,MATCH($BH$4,'3. Workings'!$D$68:$F$68,0)) -> 75.277514 | DH29: Surveyor visits avoided | DI29: =INDEX('3. Workings'!$D$117:$F$117,MATCH($BH$4,'3. Workings'!$D$100:$F$100,0)) -> 123438.33
DH31: Table S5 — Governance and moat spend (Rs Cr)
CZ32: Current Cost / Claim | DA32: =INDEX('5. Investor Metrics'!$D$7:$F$7,MATCH($BH$4,'5. Investor Metrics'!$D$6:$F$6,0)) -> 1750 | DH32: Component | DI32: Value
CZ33: ClaimPulse Cost / Claim | DA33: =INDEX('5. Investor Metrics'!$D$9:$F$9,MATCH($BH$4,'5. Investor Metrics'!$D$6:$F$6,0)) -> 246 | DH33: Capture Integrity Gate build | DI33: =INDEX('3. Workings'!$D$120:$F$120,MATCH($BH$4,'3. Workings'!$D$100:$F$100,0)) -> 1.9148541
E34: Both sides of the combined ratio move. Neither side carries the case alone. | BJ34: ="At the "&$BH$4&" rollout, ClaimPulse releases "&TEXT(DI22,"0")&" FTE of claims-handling capacity and lets the same team clear "&TEXT(DI23,"0.0")&"x the claims it handles today." -> At the Aggressive rollout, ClaimPulse releases 293 FTE of claims-handling capacity and lets the same team clear 5.7x the claims it handles today. | DB34: Gross Annual Benefit | DC34: =INDEX('3. Workings'!$D$69:$F$69,MATCH($BH$4,'3. Workings'!$D$68:$F$68,0)) -> 80.568845 | DH34: Governance, audit and explainability build | DI34: =INDEX('3. Workings'!$D$119:$F$119,MATCH($BH$4,'3. Workings'!$D$100:$F$100,0)) -> 1.0013452
DB35: Annual Run Cost | DC35: =-INDEX('3. Workings'!$D$70:$F$70,MATCH($BH$4,'3. Workings'!$D$68:$F$68,0)) -> -5.2913309 | DH35: Rest of the build | DI35: ='3. Workings'!$D$55-DI33-DI34 -> 6.9742705
DB36: Net Annual Benefit | DC36: =INDEX('3. Workings'!$D$71:$F$71,MATCH($BH$4,'3. Workings'!$D$68:$F$68,0)) -> 75.277514 | DH36: Annual compliance and legal run cost | DI36: =INDEX('3. Workings'!$D$121:$F$121,MATCH($BH$4,'3. Workings'!$D$100:$F$100,0)) -> 0.3699996
F37: THE STAKEHOLDER SCORECARD | AQ37: SURVEYORS: REDEPLOYED, NOT DISPLACED | BL37: ="WHAT THE BUILD BUYS THE REGULATOR · "&TEXT(DI37,"0.0%")&" OF THE BUILD" -> WHAT THE BUILD BUYS THE REGULATOR · 29.5% OF THE BUILD | DH37: Gate + governance as share of build | DI37: =INDEX('3. Workings'!$D$122:$F$122,MATCH($BH$4,'3. Workings'!$D$100:$F$100,0)) -> 0.29484942
F39: Stakeholder | Q39: Outcome | AB39: Value | DH39: Table S6 — Who funds vs who books (Rs Cr)
DH40: Entity | DI40: Value
F41: Policyholder | Q41: Claimant-days returned per year | AB41: =DI12 -> 1944839.4 | DH41: BFDL — capital deployed (one-off) | DI41: =INDEX('3. Workings'!$D$126:$F$126,MATCH($BH$4,'3. Workings'!$D$100:$F$100,0)) -> 9.8904698
DH42: Bajaj General — annual underwriting value | DI42: =INDEX('3. Workings'!$D$127:$F$127,MATCH($BH$4,'3. Workings'!$D$100:$F$100,0)) -> 74.317438
F43: Claims operations | Q43: FTE capacity released | AB43: =DI22 -> 293.10253 | DH43: BFDL — annual distribution value | DI43: =INDEX('3. Workings'!$D$128:$F$128,MATCH($BH$4,'3. Workings'!$D$100:$F$100,0)) -> 0.96007586
...

Sheet 1. Assumptions and Sources
B2: ClaimPulse · Assumptions and Sources
B3: Team Finsighters · NMIMS Mumbai · PS_BFDL Motor Insurance Claims TAT Reduction. Every input lives here. Sheets 1 to 3 contain no typed numbers, only formulas that read this sheet.
B5: TABLE A — FILED AND EXTERNAL DATA
B6: Ref | C6: Item | D6: Value | E6: Unit | F6: Tier | G6: Source
B7: A-01 | C7: Motor OD GDPI, FY2025-26 | D7: 3317.3 | E7: Rs Cr | F7: TIER 1 FILED | G7: GI Council segment-wise GDPI filings, Jun'25-Jun'26
B8: A-02 | C8: Net earned premium / GDPI | D8: 0.4988 | E8: ratio | F8: TIER 1 FILED | G8: Bajaj General FY2026: net earned premium Rs 9,519 Cr on gross direct premium Rs 19,082 Cr. Cross-checks to Q1 FY2027 filed: NEP Rs 2,669 Cr on GWP Rs 5,789 Cr, 46.1%. Motor OD retention runs above the whole-book blend, so this basis is conservative for Motor OD. Three bases are carried at Table P.
B9: A-03 | C9: Net incurred claims ratio | D9: 0.746 | E9: ratio | F9: TIER 1 FILED | G9: IRDAI Financial Highlights FY24-25, up 0.8 pp
B10: A-04 | C10: Group combined ratio, FY2024-25 | D10: 1.023 | E10: ratio | F10: TIER 1 FILED | G10: Crossed 100%, was 99.85% a year earlier
B11: A-05 | C11: Bajaj total GDPI, FY2025-26 | D11: 20461 | E11: Rs Cr | F11: TIER 1 FILED | G11: Motor is Rs 7,278 Cr, 35.6% of the book
B12: A-06 | C12: Motor OD market growth p.a. | D12: 0.087 | E12: ratio | F12: TIER 2 | G12: Motor sector research
B13: A-07 | C13: Salary inflation p.a. | D13: 0.069 | E13: ratio | F13: TIER 1 | G13: India talent outlook 2026
B14: A-08 | C14: FX rate | D14: 95.3 | E14: Rs / USD | F14: Market | G14: Spot, August 2026
B15: A-09 | C15: Discount rate (WACC) | D15: 0.12 | E15: ratio | F15: Standard | G15: Indian corporate project hurdle rate
B16: A-10 | C16: India regulated-sector cost uplift | D16: 1.314 | E16: x | F16: TIER 2 | G16: Compliance overhead applied to USD build benchmarks
B17: A-11 | C17: IRDAI surveyor exemption threshold | D17: 50000 | E17: Rs | F17: TIER 1 | G17: Master Circular on Protection of Policyholders' Interests, 2024
B18: A-12 | C18: API / inference price deflation p.a. | D18: -0.3 | E18: ratio | F18: TIER 2 | G18: Conservative end of a 30-50% observed range
B19: A-13 | C19: GPU price deflation p.a. | D19: -0.1 | E19: ratio | F19: TIER 2 | G19: Deflation slowing after a steep fall from peak
B21: TABLE B — OPERATING ASSUMPTIONS
B22: Ref | C22: Assumption | D22: Value | E22: Unit | F22: Tier | G22: Basis
B23: B-01 | C23: Average claim size | D23: =F150 -> 45000 | E23: Rs | F23: TIER 4 | G23: Conservative, and sits inside the Rs 50,000 surveyor corridor. A lower figure would mean more claims and more benefit.
B24: B-02 | C24: Manual touches per claim today | D24: =F147 -> 7 | E24: touches | F24: TIER 4 | G24: Workflow mapping. The largest single driver of the labour line, and confirmed by data request 1.
B25: B-03 | C25: Green lane share | D25: 0.65 | E25: ratio | F25: TIER 2 | G25: Auto-settle. Clean docs, intact EXIF, no synthetic flags.
B26: B-04 | C26: Amber lane share | D26: 0.25 | E26: ratio | F26: TIER 4 | G26: Signals inconclusive, not contradictory. One reviewer.
B27: B-05 | C27: Red lane share | D27: 0.1 | E27: ratio | F27: TIER 4 | G27: Hard contradiction at the capture gate. Investigate.
B28: B-06 | C28: Touches, green lane | D28: 0.2 | E28: touches | F28: TIER 4 | G28: Zero human touch in practice
B29: B-07 | C29: Touches, amber lane | D29: 2 | E29: touches | F29: TIER 4 | G29: One reviewer on an AI-prepared file
B30: B-08 | C30: Touches, red lane | D30: 6 | E30: touches | F30: TIER 4 | G30: Investigation with evidence pack pre-attached
B31: B-09 | C31: Claim TAT today | D31: 9.8 | E31: days | F31: TIER 2 | G31: Industry-typical 7-10+ days for non-complex motor claims
B32: B-10 | C32: TAT, green lane | D32: 1.5 | E32: days | F32: TIER 4 | G32: Auto-settlement
B33: B-11 | C33: TAT, amber lane | D33: 3.5 | E33: days | F33: TIER 4 | G33: Single assisted review
B34: B-12 | C34: TAT, red lane | D34: 7 | E34: days | F34: TIER 4 | G34: Full investigation, still faster than today
B35: B-13 | C35: Fraud detection rate (recall), today | D35: 0.62 | E35: ratio | F35: TIER 4 | G35: Share of fraudulent claims the existing rule-based engine currently catches.
B36: B-14 | C36: Fraud detection rate (recall), TARGET | D36: =F149 -> 0.9 | E36: ratio | F36: TARGET | G36: A target for the share of fraudulent claims caught. Published graph-AI lift runs +10 to 20 pp against the +28 pp modelled here, which is why F-02 tests an 82% landing and Sheet 8 runs the full curve.
B37: B-15 | C37: of the uplift, from the Capture Integrity Gate | D37: 0.1 | E37: pp | F37: TIER 4 | G37: EXIF and metadata contradiction catches crude attempts at intake, before any model runs.
B38: B-16 | C38: of the uplift, from the fraud and duplicate graph | D38: 0.18 | E38: pp | F38: TIER 4 | G38: Graph engine catches rings: same garage, vehicle, 3 claims in 30 days.
B39: B-17 | C39: Fraud leakage pool, % of claims value | D39: 0.0315 | E39: ratio | F39: TIER 2 PROXY | G39: Derived from the 8 to 10 per cent industry fraud and waste benchmark, applied to motor as a proxy. See H-01.
B40: B-18 | C40: Synthetic-media fraud, % of claims value | D40: 0.01 | E40: ratio | F40: TIER 4 | G40: Forward-looking. A NEW vector, so additive to B-17 rather than inside it. Sensitivity 0.5% to 2.0%.
B41: B-19 | C41: Gate detection rate on synthetic media | D41: 0.85 | E41: ratio | F41: TIER 4 | G41: Diffusion and GAN artefact screening on live-captured frames
B42: B-20 | C42: Live-capture friction: claims downgraded | D42: 0.08 | E42: ratio | F42: TIER 4 | G42: Honest claimants who cannot use live capture drop from green to amber. A real cost of the hard rule.
B43: B-21 | C43: Average Motor OD premium per policy | D43: 7000 | E43: Rs | F43: TIER 4 | G43: Used only to size the renewal line
...

Sheet 2. Summary
B2: ClaimPulse · Investment Summary
B3: Team Finsighters · NMIMS Mumbai · PS_BFDL Motor Insurance Claims TAT Reduction. Three implementation plans. Every figure is a formula reading Sheets 2 to 4 — nothing on this sheet is typed.
B5: PART 1 — HEADLINE FIGURES
B6: Ref | C6: Metric | D6: Conservative | E6: Base | F6: Aggressive | G6: Unit
B7: H-01 | C7: Rollout of the addressable Motor OD book | D7: ='3. Workings'!D12 -> 0.2 | E7: ='3. Workings'!E12 -> 0.6 | F7: ='3. Workings'!F12 -> 1 | G7: ratio
B8: H-02 | C8: Claims on the platform, per month | D8: ='3. Workings'!D14 -> 4571.7898 | E8: ='3. Workings'!E14 -> 13715.369 | F8: ='3. Workings'!F14 -> 22858.949 | G8: claims
B9: H-03 | C9: Claim TAT on ClaimPulse (9.8 days today) | D9: ='3. Workings'!D23 -> 2.71 | E9: ='3. Workings'!E23 -> 2.71 | F9: ='3. Workings'!F23 -> 2.71 | G9: days
B10: H-04 | C10: Blended TAT across the whole Motor OD book | D10: ='3. Workings'!D24 -> 8.382 | E10: ='3. Workings'!E24 -> 5.546 | F10: ='3. Workings'!F24 -> 2.71 | G10: days
B11: H-05 | C11: TAT reduction vs today | D11: ='3. Workings'!D26 -> 0.14469388 | E11: ='3. Workings'!E26 -> 0.43408163 | F11: ='3. Workings'!F26 -> 0.72346939 | G11: %
B12: H-06 | C12: Manual touches per claim (7 today) | D12: ='3. Workings'!D19 -> 1.23 | E12: ='3. Workings'!E19 -> 1.23 | F12: ='3. Workings'!F19 -> 1.23 | G12: touches
B13: H-07 | C13: Gross annual benefit | D13: ='3. Workings'!D36 -> 15.359972 | E13: ='3. Workings'!E36 -> 47.210612 | F13: ='3. Workings'!F36 -> 80.568845 | G13: Rs Cr
B14: H-08 | C14: Annual run cost | D14: ='3. Workings'!D65 -> 2.5098822 | E14: ='3. Workings'!E65 -> 3.9006065 | F14: ='3. Workings'!F65 -> 5.2913309 | G14: Rs Cr
B15: H-09 | C15: NET ANNUAL BENEFIT | D15: ='3. Workings'!D71 -> 12.85009 | E15: ='3. Workings'!E71 -> 43.310005 | F15: ='3. Workings'!F71 -> 75.277514 | G15: Rs Cr
B16: H-10 | C16: Net monthly benefit | D16: ='3. Workings'!D72 -> 1.0708408 | E16: ='3. Workings'!E72 -> 3.6091671 | F16: ='3. Workings'!F72 -> 6.2731261 | G16: Rs Cr
B17: H-11 | C17: Build cost, one-off (same in all three plans) | D17: ='3. Workings'!D73 -> 9.8904698 | E17: ='3. Workings'!E73 -> 9.8904698 | F17: ='3. Workings'!F73 -> 9.8904698 | G17: Rs Cr
B18: H-12 | C18: Payback on steady-state economics | D18: ='3. Workings'!D74 -> 9.2361717 | E18: ='3. Workings'!E74 -> 2.7403746 | F18: ='3. Workings'!F74 -> 1.5766413 | G18: months
B19: H-13 | C19: Payback — REALISTIC DOWNSIDE | D19: ='3. Workings'!D96 -> 28.634321 | E19: ='3. Workings'!E96 -> 7.3884554 | F19: ='3. Workings'!F96 -> 4.2414317 | G19: months
B20: H-14 | C20: Payback — absolute floor, labour only | D20: ='3. Workings'!D97 -> 2286.0024 | E20: ='3. Workings'!E97 -> 31.358536 | F20: ='3. Workings'!F97 -> 15.787552 | G20: months
B21: H-15 | C21: Combined ratio impact — Motor OD basis | D21: ='3. Workings'!D82 -> 0.76499125 | E21: ='3. Workings'!E82 -> 2.5826285 | F21: ='3. Workings'!F82 -> 4.4913773 | G21: pp
B22: H-16 | C22: Combined ratio impact — group basis | D22: ='3. Workings'!D85 -> 0.12402646 | E22: ='3. Workings'!E85 -> 0.41871627 | F22: ='3. Workings'!F85 -> 0.72817779 | G22: pp
B23: H-17 | C23: 3-year net benefit | D23: ='4. Forecast'!D47 -> 32.217718 | E23: ='4. Forecast'!E47 -> 111.49047 | F23: ='4. Forecast'!F47 -> 194.73062 | G23: Rs Cr
B24: H-18 | C24: 3-year NPV at 12% | D24: ='4. Forecast'!D49 -> 14.91756 | E24: ='4. Forecast'!E49 -> 76.277313 | F24: ='4. Forecast'!F49 -> 140.7126 | G24: Rs Cr
B25: H-19 | C25: Payback from project kickoff (includes the 10-month build) | D25: ='4. Forecast'!D50 -> 27.21363 | E25: ='4. Forecast'!E50 -> 16.842971 | F25: ='4. Forecast'!F50 -> 13.83294 | G25: months
B27: PART 1B — WHERE THE BENEFIT COMES FROM (Rs Cr per year, steady state)
B28: Ref | C28: Benefit line | D28: Conservative | E28: Base | F28: Aggressive | G28: Drives which ratio
B29: H-20 | C29: Labour: manual touches removed | D29: ='3. Workings'!D30 -> 7.5763701 | E29: ='3. Workings'!E30 -> 23.741305 | F29: ='3. Workings'!F30 -> 41.255831 | G29: Expense ratio
B30: H-21 | C30: Fraud avoided: fraud and duplicate graph | D30: ='3. Workings'!D31 -> 3.6836595 | E30: ='3. Workings'!E31 -> 11.050978 | F30: ='3. Workings'!F31 -> 18.418297 | G30: Loss ratio
B31: H-22 | C31: Fraud avoided: CAPTURE INTEGRITY GATE | D31: ='3. Workings'!D32 -> 2.0464775 | E31: ='3. Workings'!E32 -> 6.1394325 | F31: ='3. Workings'!F32 -> 10.232387 | G31: Loss ratio
B32: H-23 | C32: Synthetic-media exposure avoided: THE GATE | D32: ='3. Workings'!D33 -> 2.0984515 | E32: ='3. Workings'!E33 -> 6.2953546 | F32: ='3. Workings'!F33 -> 10.492258 | G32: Loss ratio
B33: H-24 | C33: Renewal retention on claimants | D33: ='3. Workings'!D34 -> 0.19201517 | E33: ='3. Workings'!E34 -> 0.57604552 | F33: ='3. Workings'!F34 -> 0.96007586 | G33: Outside both ratios
B34: H-25 | C34: less: live-capture friction cost | D34: ='3. Workings'!D35 -> -0.23700158 | E34: ='3. Workings'!E35 -> -0.59250396 | F34: ='3. Workings'!F35 -> -0.79000528 | G34: Expense ratio
B35: H-26 | C35: GROSS ANNUAL BENEFIT | D35: ='3. Workings'!D36 -> 15.359972 | E35: ='3. Workings'!E36 -> 47.210612 | F35: ='3. Workings'!F36 -> 80.568845
C36: Rows H-22, H-23 and part of the TAT gain are the Capture Integrity Gate. It carries its own build cost and its own benefit lines rather than sitting on a slide as a claim.
B38: PART 2 — KEY ASSUMPTIONS AND DATA SOURCES · full register on Sheet 1
B39: Ref | C39: Assumption | D39: Value | E39: Tier | F39: Source / basis | G39: Why it matters
B40: A-01 | C40: ='1. Assumptions and Sources'!$C$7 -> Motor OD GDPI, FY2025-26 | D40: ='1. Assumptions and Sources'!$D$7 -> 3317.3 | E40: ='1. Assumptions and Sources'!$F$7 -> TIER 1 FILED | F40: ='1. Assumptions and Sources'!$G$7 -> GI Council segment-wise GDPI filings, Jun'25-Jun'26 | G40: Top of the benefit chain. Everything scales from this.
B41: A-02 | C41: ='1. Assumptions and Sources'!$C$8 -> Net earned premium / GDPI | D41: ='1. Assumptions and Sources'!$D$8 -> 0.4988 | E41: ='1. Assumptions and Sources'!$F$8 -> TIER 1 FILED | F41: ='1. Assumptions and Sources'!$G$8 -> Bajaj General FY2026: net earned premium Rs 9,519 Cr on gross direct premium Rs 19,082 Cr. Cross-checks to Q1 FY2027 filed: NEP Rs 2,669 Cr on GWP Rs 5,789 Cr, 46.1%. Motor OD retention runs above the whole-book blend, so this basis is conservative for Motor OD. Three bases are carried at Table P. | G41: Converts gross direct premium to net earned premium. Filed FY2026 basis; three bases are carried at Table P.
B42: A-03 | C42: ='1. Assumptions and Sources'!$C$9 -> Net incurred claims ratio | D42: ='1. Assumptions and Sources'!$D$9 -> 0.746 | E42: ='1. Assumptions and Sources'!$F$9 -> TIER 1 FILED | F42: ='1. Assumptions and Sources'!$G$9 -> IRDAI Financial Highlights FY24-25, up 0.8 pp | G42: Converts earned premium into the claims pool ClaimPulse acts on.
B43: A-11 | C43: ='1. Assumptions and Sources'!$C$17 -> IRDAI surveyor exemption threshold | D43: ='1. Assumptions and Sources'!$D$17 -> 50000 | E43: ='1. Assumptions and Sources'!$F$17 -> TIER 1 | F43: ='1. Assumptions and Sources'!$G$17 -> Master Circular on Protection of Policyholders' Interests, 2024 | G43: The regulatory corridor the green lane is scoped to sit inside.
B44: A-08 | C44: ='1. Assumptions and Sources'!$C$14 -> FX rate | D44: ='1. Assumptions and Sources'!$D$14 -> 95.3 | E44: ='1. Assumptions and Sources'!$F$14 -> Market | F44: ='1. Assumptions and Sources'!$G$14 -> Spot, August 2026 | G44: Every USD build benchmark converts at this rate.
...

Sheet 3. Workings
B2: Detailed Workings
B3: Filed premium to net benefit, for all three implementation plans side by side. Every cell is a formula reading Sheet 1. Nothing here is typed.
B5: PART A — FROM FILED PREMIUM TO CLAIMS IN SCOPE
B6: Ref | C6: Step | D6: Conservative | E6: Base | F6: Aggressive | G6: Unit | H6: How it is derived
B7: W-01 | C7: Motor OD GDPI, FY2025-26 | D7: ='1. Assumptions and Sources'!$D$7 -> 3317.3 | E7: ='1. Assumptions and Sources'!$D$7 -> 3317.3 | F7: ='1. Assumptions and Sources'!$D$7 -> 3317.3 | G7: Rs Cr | H7: A-01. Bajaj's own filed Motor OD gross direct premium.
B8: W-02 | C8: Motor OD net earned premium | D8: =D7*'1. Assumptions and Sources'!$D$8 -> 1654.6692 | E8: =E7*'1. Assumptions and Sources'!$D$8 -> 1654.6692 | F8: =F7*'1. Assumptions and Sources'!$D$8 -> 1654.6692 | G8: Rs Cr | H8: W-01 x A-02 filed NEP/GDPI ratio.
B9: W-03 | C9: Annual incurred claims pool | D9: =D8*'1. Assumptions and Sources'!$D$9 -> 1234.3833 | E9: =E8*'1. Assumptions and Sources'!$D$9 -> 1234.3833 | F9: =F8*'1. Assumptions and Sources'!$D$9 -> 1234.3833 | G9: Rs Cr | H9: W-02 x A-03 net incurred claims ratio. This is the pool ClaimPulse acts on.
B10: W-04 | C10: Average claim size | D10: ='1. Assumptions and Sources'!$D$23 -> 45000 | E10: ='1. Assumptions and Sources'!$D$23 -> 45000 | F10: ='1. Assumptions and Sources'!$D$23 -> 45000 | G10: Rs | H10: B-01. Reconciled to an in-band claim frequency at Part K.
B11: W-05 | C11: Annual claim count, full book | D11: =D9*10000000/D10 -> 274307.39 | E11: =E9*10000000/E10 -> 274307.39 | F11: =F9*10000000/F10 -> 274307.39 | G11: claims | H11: Claims pool in rupees divided by average claim size.
B12: W-06 | C12: Rollout of the addressable book | D12: ='1. Assumptions and Sources'!D$54 -> 0.2 | E12: ='1. Assumptions and Sources'!E$54 -> 0.6 | F12: ='1. Assumptions and Sources'!F$54 -> 1 | G12: ratio | H12: C-01. THE defining lever between the three plans.
B13: W-07 | C13: Annual claims on the platform | D13: =D11*D12 -> 54861.478 | E13: =E11*E12 -> 164584.43 | F13: =F11*F12 -> 274307.39 | G13: claims | H13: Full-book count x rollout.
B14: W-08 | C14: Monthly claims on the platform | D14: =D13/12 -> 4571.7898 | E14: =E13/12 -> 13715.369 | F14: =F13/12 -> 22858.949 | G14: claims | H14: Annual claim count divided by twelve.
B15: W-09 | C15: Annual claims VALUE on the platform | D15: =D9*D12 -> 246.87665 | E15: =E9*E12 -> 740.62995 | F15: =F9*F12 -> 1234.3833 | G15: Rs Cr | H15: Claims pool x rollout. Drives both fraud lines.
B17: PART B — LANE MIX, MANUAL TOUCHES AND TAT · the Trust Score routing
B18: Ref | C18: Step | D18: Conservative | E18: Base | F18: Aggressive | G18: Unit | H18: How it is derived
B19: W-10 | C19: Blended manual touches after ClaimPulse | D19: ='1. Assumptions and Sources'!$D$25*'1. Assumptions and Sources'!$D$28+'1. Assumptions and Sources'!$D$26*'1. Assumptions and Sources'!$D$29+'1. Assumptions and Sources'!$D$27*'1. Assumptions and Sources'!$D$30 -> 1.23 | E19: ='1. Assumptions and Sources'!$D$25*'1. Assumptions and Sources'!$D$28+'1. Assumptions and Sources'!$D$26*'1. Assumptions and Sources'!$D$29+'1. Assumptions and Sources'!$D$27*'1. Assumptions and Sources'!$D$30 -> 1.23 | F19: ='1. Assumptions and Sources'!$D$25*'1. Assumptions and Sources'!$D$28+'1. Assumptions and Sources'!$D$26*'1. Assumptions and Sources'!$D$29+'1. Assumptions and Sources'!$D$27*'1. Assumptions and Sources'!$D$30 -> 1.23 | G19: touches | H19: Lane-weighted: 65% green x 0.2 + 25% amber x 2 + 10% red x 6.
B20: W-11 | C20: Manual touches removed per claim | D20: ='1. Assumptions and Sources'!$D$24-D19 -> 5.77 | E20: ='1. Assumptions and Sources'!$D$24-E19 -> 5.77 | F20: ='1. Assumptions and Sources'!$D$24-F19 -> 5.77 | G20: touches | H20: 7 today less the blended figure above.
B21: W-12 | C21: Claim TAT on ClaimPulse | D21: ='1. Assumptions and Sources'!$D$25*'1. Assumptions and Sources'!$D$32+'1. Assumptions and Sources'!$D$26*'1. Assumptions and Sources'!$D$33+'1. Assumptions and Sources'!$D$27*'1. Assumptions and Sources'!$D$34 -> 2.55 | E21: ='1. Assumptions and Sources'!$D$25*'1. Assumptions and Sources'!$D$32+'1. Assumptions and Sources'!$D$26*'1. Assumptions and Sources'!$D$33+'1. Assumptions and Sources'!$D$27*'1. Assumptions and Sources'!$D$34 -> 2.55 | F21: ='1. Assumptions and Sources'!$D$25*'1. Assumptions and Sources'!$D$32+'1. Assumptions and Sources'!$D$26*'1. Assumptions and Sources'!$D$33+'1. Assumptions and Sources'!$D$27*'1. Assumptions and Sources'!$D$34 -> 2.55 | G21: days | H21: Lane-weighted: 65% x 1.5d + 25% x 3.5d + 10% x 7d.
B22: W-13 | C22: Claim TAT today | D22: ='1. Assumptions and Sources'!$D$31 -> 9.8 | E22: ='1. Assumptions and Sources'!$D$31 -> 9.8 | F22: ='1. Assumptions and Sources'!$D$31 -> 9.8 | G22: days | H22: B-09. Industry-typical 7 to 10+ days.
B23: W-14 | C23: TAT on ClaimPulse, after live-capture friction | D23: =('1. Assumptions and Sources'!$D$25-'1. Assumptions and Sources'!$D$42)*'1. Assumptions and Sources'!$D$32+('1. Assumptions and Sources'!$D$26+'1. Assumptions and Sources'!$D$42)*'1. Assumptions and Sources'!$D$33+'1. Assumptions and Sources'!$D$27*'1. Assumptions and Sources'!$D$34 -> 2.71 | E23: =('1. Assumptions and Sources'!$D$25-'1. Assumptions and Sources'!$D$42)*'1. Assumptions and Sources'!$D$32+('1. Assumptions and Sources'!$D$26+'1. Assumptions and Sources'!$D$42)*'1. Assumptions and Sources'!$D$33+'1. Assumptions and Sources'!$D$27*'1. Assumptions and Sources'!$D$34 -> 2.71 | F23: =('1. Assumptions and Sources'!$D$25-'1. Assumptions and Sources'!$D$42)*'1. Assumptions and Sources'!$D$32+('1. Assumptions and Sources'!$D$26+'1. Assumptions and Sources'!$D$42)*'1. Assumptions and Sources'!$D$33+'1. Assumptions and Sources'!$D$27*'1. Assumptions and Sources'!$D$34 -> 2.71 | G23: days | H23: 8% of claims fall from green to amber because live capture was not possible. The honest figure.
B24: W-15 | C24: Blended TAT across the whole Motor OD book | D24: =D12*D23+(1-D12)*D22 -> 8.382 | E24: =E12*E23+(1-E12)*E22 -> 5.546 | F24: =F12*F23+(1-F12)*F22 -> 2.71 | G24: days | H24: Platform TAT on the rolled-out share, 9.8 days on the rest. This is the number that improves as rollout rises.
B25: W-16 | C25: TAT reduction vs today | D25: =D22-D24 -> 1.418 | E25: =E22-E24 -> 4.254 | F25: =F22-F24 -> 7.09 | G25: days | H25: W-13 less W-15.
B26: W-17 | C26: TAT reduction | D26: =D25/D22 -> 0.14469388 | E26: =E25/E22 -> 0.43408163 | F26: =F25/F22 -> 0.72346939 | G26: % | H26: As a percentage of today's TAT.
B28: PART C — ANNUAL BENEFIT LINES (Rs Cr)
B29: Ref | C29: Benefit line | D29: Conservative | E29: Base | F29: Aggressive | G29: Unit | H29: How it is derived
B30: W-18 | C30: Labour: manual touches removed | D30: =D13*('1. Assumptions and Sources'!$D$24*'1. Assumptions and Sources'!$D$51-D19*'1. Assumptions and Sources'!D$55)/10000000 -> 7.5763701 | E30: =E13*('1. Assumptions and Sources'!$D$24*'1. Assumptions and Sources'!$D$51-E19*'1. Assumptions and Sources'!E$55)/10000000 -> 23.741305 | F30: =F13*('1. Assumptions and Sources'!$D$24*'1. Assumptions and Sources'!$D$51-F19*'1. Assumptions and Sources'!F$55)/10000000 -> 41.255831 | G30: Rs Cr | H30: Claims x (baseline touches at B-28 less residual touches at the plan rate). Lands in the EXPENSE ratio. Tests at H-03 and H-04.
B31: W-19 | C31: Fraud avoided: fraud and duplicate graph | D31: =D15*'1. Assumptions and Sources'!$D$39*(1-(1-'1. Assumptions and Sources'!$D$36)/(1-'1. Assumptions and Sources'!$D$35))*('1. Assumptions and Sources'!$D$38/('1. Assumptions and Sources'!$D$37+'1. Assumptions and Sources'!$D$38)) -> 3.6836595 | E31: =E15*'1. Assumptions and Sources'!$D$39*(1-(1-'1. Assumptions and Sources'!$D$36)/(1-'1. Assumptions and Sources'!$D$35))*('1. Assumptions and Sources'!$D$38/('1. Assumptions and Sources'!$D$37+'1. Assumptions and Sources'!$D$38)) -> 11.050978 | F31: =F15*'1. Assumptions and Sources'!$D$39*(1-(1-'1. Assumptions and Sources'!$D$36)/(1-'1. Assumptions and Sources'!$D$35))*('1. Assumptions and Sources'!$D$38/('1. Assumptions and Sources'!$D$37+'1. Assumptions and Sources'!$D$38)) -> 18.418297 | G31: Rs Cr | H31: Claims value x leakage pool x reduction in the UNDETECTED share, then the graph's 18 of 28 pp share. Hits the LOSS ratio.
B32: W-20 | C32: Fraud avoided: CAPTURE INTEGRITY GATE | D32: =D15*'1. Assumptions and Sources'!$D$39*(1-(1-'1. Assumptions and Sources'!$D$36)/(1-'1. Assumptions and Sources'!$D$35))*('1. Assumptions and Sources'!$D$37/('1. Assumptions and Sources'!$D$37+'1. Assumptions and Sources'!$D$38)) -> 2.0464775 | E32: =E15*'1. Assumptions and Sources'!$D$39*(1-(1-'1. Assumptions and Sources'!$D$36)/(1-'1. Assumptions and Sources'!$D$35))*('1. Assumptions and Sources'!$D$37/('1. Assumptions and Sources'!$D$37+'1. Assumptions and Sources'!$D$38)) -> 6.1394325 | F32: =F15*'1. Assumptions and Sources'!$D$39*(1-(1-'1. Assumptions and Sources'!$D$36)/(1-'1. Assumptions and Sources'!$D$35))*('1. Assumptions and Sources'!$D$37/('1. Assumptions and Sources'!$D$37+'1. Assumptions and Sources'!$D$38)) -> 10.232387 | G32: Rs Cr | H32: Same chain, the gate's 10 of 28 pp share. EXIF and metadata contradiction caught at intake.
B33: W-21 | C33: Synthetic-media exposure avoided: THE GATE | D33: =D15*'1. Assumptions and Sources'!$D$40*'1. Assumptions and Sources'!$D$41 -> 2.0984515 | E33: =E15*'1. Assumptions and Sources'!$D$40*'1. Assumptions and Sources'!$D$41 -> 6.2953546 | F33: =F15*'1. Assumptions and Sources'!$D$40*'1. Assumptions and Sources'!$D$41 -> 10.492258 | G33: Rs Cr | H33: Claims value x synthetic-fraud incidence x gate detection rate. A NEW vector, additive to W-19 and W-20. Nobody else defends against it.
B34: W-22 | C34: Renewal retention on the claimant cohort | D34: =D13*'1. Assumptions and Sources'!$D$43*'1. Assumptions and Sources'!$D$44*'1. Assumptions and Sources'!$D$45/10000000 -> 0.19201517 | E34: =E13*'1. Assumptions and Sources'!$D$43*'1. Assumptions and Sources'!$D$44*'1. Assumptions and Sources'!$D$45/10000000 -> 0.57604552 | F34: =F13*'1. Assumptions and Sources'!$D$43*'1. Assumptions and Sources'!$D$44*'1. Assumptions and Sources'!$D$45/10000000 -> 0.96007586 | G34: Rs Cr | H34: Claims x average premium x renewal uplift x retained value. Distribution income, so it sits OUTSIDE the combined ratio.
B35: W-23 | C35: less: live-capture friction cost | D35: =-D13*'1. Assumptions and Sources'!$D$42*('1. Assumptions and Sources'!$D$29-'1. Assumptions and Sources'!$D$28)*'1. Assumptions and Sources'!D$55/10000000 -> -0.23700158 | E35: =-E13*'1. Assumptions and Sources'!$D$42*('1. Assumptions and Sources'!$D$29-'1. Assumptions and Sources'!$D$28)*'1. Assumptions and Sources'!E$55/10000000 -> -0.59250396 | F35: =-F13*'1. Assumptions and Sources'!$D$42*('1. Assumptions and Sources'!$D$29-'1. Assumptions and Sources'!$D$28)*'1. Assumptions and Sources'!F$55/10000000 -> -0.79000528 | G35: Rs Cr | H35: 8% of claims take amber-lane touches instead of green. The cost of the hard live-capture rule.
B36: W-24 | C36: GROSS ANNUAL BENEFIT | D36: =SUM(D30:D35) -> 15.359972 | E36: =SUM(E30:E35) -> 47.210612 | F36: =SUM(F30:F35) -> 80.568845 | G36: Rs Cr | H36: Sum of the six lines above.
B38: PART D — BUILD COST, ONE-OFF · identical in all three plans (you build the same system)
B39: Ref | C39: Component | D39: Rs Cr | E39: Phase | F39: Basis
B40: ='1. Assumptions and Sources'!$B$60 -> D-01 | C40: ='1. Assumptions and Sources'!$C$60 -> Document AI, OCR and field extraction | D40: ='1. Assumptions and Sources'!$D$60*'1. Assumptions and Sources'!$D$16*'1. Assumptions and Sources'!$D$14/10000000 -> 0.4382847 | E40: ='1. Assumptions and Sources'!$F$60 -> P1 | F40: ='1. Assumptions and Sources'!$G$60 -> Vendor NLP extraction band $20-45K
B41: ='1. Assumptions and Sources'!$B$61 -> D-02 | C41: ='1. Assumptions and Sources'!$C$61 -> Policy validation, RAG on actual wording | D41: ='1. Assumptions and Sources'!$D$61*'1. Assumptions and Sources'!$D$16*'1. Assumptions and Sources'!$D$14/10000000 -> 0.3130605 | E41: ='1. Assumptions and Sources'!$F$61 -> P1 | F41: ='1. Assumptions and Sources'!$G$61 -> Vendor RAG build band $20-60K
B42: ='1. Assumptions and Sources'!$B$62 -> D-03 | C42: ='1. Assumptions and Sources'!$C$62 -> EXIF and metadata forensics engine | D42: ='1. Assumptions and Sources'!$D$62*'1. Assumptions and Sources'!$D$16*'1. Assumptions and Sources'!$D$14/10000000 -> 0.3130605 | E42: ='1. Assumptions and Sources'!$F$62 -> P1 | F42: ='1. Assumptions and Sources'!$G$62 -> CAPTURE INTEGRITY GATE. Rules-based, zero model training.
B43: ='1. Assumptions and Sources'!$B$63 -> D-04 | C43: ='1. Assumptions and Sources'!$C$63 -> Synthetic and tampered image screening | D43: ='1. Assumptions and Sources'!$D$63*'1. Assumptions and Sources'!$D$16*'1. Assumptions and Sources'!$D$14/10000000 -> 0.626121 | E43: ='1. Assumptions and Sources'!$F$63 -> P2 | F43: ='1. Assumptions and Sources'!$G$63 -> CAPTURE INTEGRITY GATE. The moat. Diffusion and GAN artefact classifier tuned on own media.
B44: ='1. Assumptions and Sources'!$B$64 -> D-05 | C44: ='1. Assumptions and Sources'!$C$64 -> Guided live-capture SDK, gallery disabled | D44: ='1. Assumptions and Sources'!$D$64*'1. Assumptions and Sources'!$D$16*'1. Assumptions and Sources'!$D$14/10000000 -> 0.3756726 | E44: ='1. Assumptions and Sources'!$F$64 -> P1 | F44: ='1. Assumptions and Sources'!$G$64 -> CAPTURE INTEGRITY GATE. The hard rule that makes the other two checks reliable.
B45: ='1. Assumptions and Sources'!$B$65 -> D-06 | C45: ='1. Assumptions and Sources'!$C$65 -> CV damage assessment, 360 video and depth | D45: ='1. Assumptions and Sources'!$D$65*'1. Assumptions and Sources'!$D$16*'1. Assumptions and Sources'!$D$14/10000000 -> 1.0017936 | E45: ='1. Assumptions and Sources'!$F$65 -> P2 | F45: ='1. Assumptions and Sources'!$G$65 -> Two independent sources, $80-180K band
...

Sheet 4. Forecast
B2: Three-Year Forecast
B3: One block per implementation plan. Year 0 is the 10-month build with no benefit. Benefit ramps through Year 1 and reaches steady state in Year 3. Run cost is charged in full from Year 1, which is deliberately conservative.
B5: CONSERVATIVE · 20% rollout
B6: Ref | C6: Line | D6: Year 0 | E6: Year 1 | F6: Year 2 | G6: Year 3 | H6: 3-yr total | I6: Unit
B7: F-01 | C7: Benefit realisation factor | E7: ='1. Assumptions and Sources'!$D$46 -> 0.45 | F7: ='1. Assumptions and Sources'!$D$47 -> 0.92 | G7: ='1. Assumptions and Sources'!$D$48 -> 1 | I7: ratio
B8: F-02 | C8: Market growth factor | E8: 1 | F8: =1+'1. Assumptions and Sources'!$D$12 -> 1.087 | G8: =(1+'1. Assumptions and Sources'!$D$12)^2 -> 1.181569 | I8: x
B9: F-03 | C9: Claims processed | E9: ='3. Workings'!$D$13*E7*E8 -> 24687.665 | F9: ='3. Workings'!$D$13*F7*F8 -> 54863.672 | G9: ='3. Workings'!$D$13*G7*G8 -> 64822.622 | H9: =SUM(E9:G9) -> 144373.96 | I9: claims
B10: F-04 | C10: Gross benefit | E10: ='3. Workings'!$D$36*E7*E8 -> 6.9119875 | F10: ='3. Workings'!$D$36*F7*F8 -> 15.360587 | G10: ='3. Workings'!$D$36*G7*G8 -> 18.148867 | H10: =SUM(E10:G10) -> 40.421441 | I10: Rs Cr
B11: F-05 | C11: Run cost | E11: ='3. Workings'!$D$65*E8 -> 2.5098822 | F11: ='3. Workings'!$D$65*F8 -> 2.7282419 | G11: ='3. Workings'!$D$65*G8 -> 2.965599 | H11: =SUM(E11:G11) -> 8.2037231 | I11: Rs Cr
B12: F-06 | C12: Build cost | D12: ='3. Workings'!$D$55 -> 9.8904698 | E12: 0 | F12: 0 | G12: 0 | H12: =D12 -> 9.8904698 | I12: Rs Cr
B13: F-07 | C13: NET BENEFIT | D13: =-D12 -> -9.8904698 | E13: =E10-E11-E12 -> 4.4021053 | F13: =F10-F11-F12 -> 12.632345 | G13: =G10-G11-G12 -> 15.183268 | H13: =SUM(E13:G13) -> 32.217718 | I13: Rs Cr
B14: F-08 | C14: Risk-adjusted net benefit | D14: =D13 -> -9.8904698 | E14: =IF(E13>0,E13*(1-'1. Assumptions and Sources'!$D$50),E13) -> 3.3566053 | F14: =IF(F13>0,F13*(1-'1. Assumptions and Sources'!$D$50),F13) -> 9.6321628 | G14: =IF(G13>0,G13*(1-'1. Assumptions and Sources'!$D$50),G13) -> 11.577242 | H14: =SUM(E14:G14) -> 24.56601 | I14: Rs Cr
B15: F-09 | C15: Cumulative net position | D15: =D13 -> -9.8904698 | E15: =D15+E13 -> -5.4883645 | F15: =E15+F13 -> 7.1439802 | G15: =F15+G13 -> 22.327248 | I15: Rs Cr
B18: BASE · 60% rollout
B19: Ref | C19: Line | D19: Year 0 | E19: Year 1 | F19: Year 2 | G19: Year 3 | H19: 3-yr total | I19: Unit
B20: F-01 | C20: Benefit realisation factor | E20: ='1. Assumptions and Sources'!$D$46 -> 0.45 | F20: ='1. Assumptions and Sources'!$D$47 -> 0.92 | G20: ='1. Assumptions and Sources'!$D$48 -> 1 | I20: ratio
B21: F-02 | C21: Market growth factor | E21: 1 | F21: =1+'1. Assumptions and Sources'!$D$12 -> 1.087 | G21: =(1+'1. Assumptions and Sources'!$D$12)^2 -> 1.181569 | I21: x
B22: F-03 | C22: Claims processed | E22: ='3. Workings'!$E$13*E20*E21 -> 74062.995 | F22: ='3. Workings'!$E$13*F20*F21 -> 164591.02 | G22: ='3. Workings'!$E$13*G20*G21 -> 194467.86 | H22: =SUM(E22:G22) -> 433121.88 | I22: claims
B23: F-04 | C23: Gross benefit | E23: ='3. Workings'!$E$36*E20*E21 -> 21.244775 | F23: ='3. Workings'!$E$36*F20*F21 -> 47.2125 | G23: ='3. Workings'!$E$36*G20*G21 -> 55.782595 | H23: =SUM(E23:G23) -> 124.23987 | I23: Rs Cr
B24: F-05 | C24: Run cost | E24: ='3. Workings'!$E$65*E21 -> 3.9006065 | F24: ='3. Workings'!$E$65*F21 -> 4.2399593 | G24: ='3. Workings'!$E$65*G21 -> 4.6088358 | H24: =SUM(E24:G24) -> 12.749402 | I24: Rs Cr
B25: F-06 | C25: Build cost | D25: ='3. Workings'!$D$55 -> 9.8904698 | E25: 0 | F25: 0 | G25: 0 | H25: =D25 -> 9.8904698 | I25: Rs Cr
B26: F-07 | C26: NET BENEFIT | D26: =-D25 -> -9.8904698 | E26: =E23-E24-E25 -> 17.344169 | F26: =F23-F24-F25 -> 42.972541 | G26: =G23-G24-G25 -> 51.173759 | H26: =SUM(E26:G26) -> 111.49047 | I26: Rs Cr
B27: F-08 | C27: Risk-adjusted net benefit | D27: =D26 -> -9.8904698 | E27: =IF(E26>0,E26*(1-'1. Assumptions and Sources'!$D$50),E26) -> 13.224929 | F27: =IF(F26>0,F26*(1-'1. Assumptions and Sources'!$D$50),F26) -> 32.766562 | G27: =IF(G26>0,G26*(1-'1. Assumptions and Sources'!$D$50),G26) -> 39.019992 | H27: =SUM(E27:G27) -> 85.011483 | I27: Rs Cr
B28: F-09 | C28: Cumulative net position | D28: =D26 -> -9.8904698 | E28: =D28+E26 -> 7.4536989 | F28: =E28+F26 -> 50.42624 | G28: =F28+G26 -> 101.6 | I28: Rs Cr
B31: AGGRESSIVE · 100% rollout
B32: Ref | C32: Line | D32: Year 0 | E32: Year 1 | F32: Year 2 | G32: Year 3 | H32: 3-yr total | I32: Unit
B33: F-01 | C33: Benefit realisation factor | E33: ='1. Assumptions and Sources'!$D$46 -> 0.45 | F33: ='1. Assumptions and Sources'!$D$47 -> 0.92 | G33: ='1. Assumptions and Sources'!$D$48 -> 1 | I33: ratio
B34: F-02 | C34: Market growth factor | E34: 1 | F34: =1+'1. Assumptions and Sources'!$D$12 -> 1.087 | G34: =(1+'1. Assumptions and Sources'!$D$12)^2 -> 1.181569 | I34: x
B35: F-03 | C35: Claims processed | E35: ='3. Workings'!$F$13*E33*E34 -> 123438.33 | F35: ='3. Workings'!$F$13*F33*F34 -> 274318.36 | G35: ='3. Workings'!$F$13*G33*G34 -> 324113.11 | H35: =SUM(E35:G35) -> 721869.8 | I35: claims
B36: F-04 | C36: Gross benefit | E36: ='3. Workings'!$F$36*E33*E34 -> 36.25598 | F36: ='3. Workings'!$F$36*F33*F34 -> 80.572067 | G36: ='3. Workings'!$F$36*G33*G34 -> 95.197649 | H36: =SUM(E36:G36) -> 212.0257 | I36: Rs Cr
B37: F-05 | C37: Run cost | E37: ='3. Workings'!$F$65*E34 -> 5.2913309 | F37: ='3. Workings'!$F$65*F34 -> 5.7516767 | G37: ='3. Workings'!$F$65*G34 -> 6.2520725 | H37: =SUM(E37:G37) -> 17.29508 | I37: Rs Cr
B38: F-06 | C38: Build cost | D38: ='3. Workings'!$D$55 -> 9.8904698 | E38: 0 | F38: 0 | G38: 0 | H38: =D38 -> 9.8904698 | I38: Rs Cr
B39: F-07 | C39: NET BENEFIT | D39: =-D38 -> -9.8904698 | E39: =E36-E37-E38 -> 30.964649 | F39: =F36-F37-F38 -> 74.820391 | G39: =G36-G37-G38 -> 88.945577 | H39: =SUM(E39:G39) -> 194.73062 | I39: Rs Cr
